Workbook

Sheet Table 1
A1: Table 1 | B1: 234Th activities by epoch and cruise average 234Th fluxes binned by depth
C3: 234Th activity (dpm L-1) | N3: 238U activity (dpm L-1) | O3: 234Th flux (dpm m-2 d-1) | S3: Difference
C4: EPOCH 1 | F4: EPOCH 2 | I4: EPOCH 3 | L4: CRUISE | N4: CRUISE | O4: CRUISE SS | Q4: CRUISE NSS | S4: NSS/SS percent | U4: trap depths
A5: Avg. Depth | B5: Sample depth | C5: 234Th | F5: 234Th | I5: 234Th | L5: 234Th | N5: 238U | O5: 234Th fluxd | Q5: 234Th fluxe | S5: Not on Elementa | W5: NSS/SS
A6: (m)a | B6: range (m)b | C6: average | D6: st devc | E6: n= | F6: average | G6: st devc | H6: n= | I6: average | J6: st devc | K6: n= | L6: average | M6: st devc | N6: average | O6: average | P6: uncert | Q6: average | R6: uncert | S6: Difference | T6: error | W6: average | X6: stdev
A7: 5 | B7: 4-9 | C7: 1.3536437 | D7: 0.17308557 | E7: 18 | F7: 1.3108621 | G7: 0.15550032 | H7: 21 | I7: 1.4570313 | J7: 0.087589337 | K7: 19 | L7: 1.3720221 | M7: 0.15406387 | N7: 2.2232237 | O7: 324.28513 | P7: 79.778754 | Q7: 220.63376 | R7: 120.38089 | S7: =Q7/O7 -> 0.68036964 | T7: =((((R7/Q7)^2+(P7/O7)^2))^0.5)*S7 -> 0.40721005 | W7: =AVERAGE(S7:S19) -> 0.70705883 | X7: =STDEV(S7:S19) -> 0.091652581
A8: 20 | B8: 15-24 | C8: 1.367685 | D8: 0.1189843 | E8: 17 | F8: 1.3437554 | G8: 0.13986775 | H8: 21 | I8: 1.5030798 | J8: 0.12565635 | K8: 16 | L8: 1.398496 | M8: 0.14463283 | N8: 2.2235081 | O8: 666.38501 | P8: 144.75212 | Q8: 445.27711 | R8: 195.48947 | S8: =Q8/O8 -> 0.66819797 | T8: =((((R8/Q8)^2+(P8/O8)^2))^0.5)*S8 -> 0.32730161
A9: 35 | B9: 25-42 | C9: 1.4252616 | D9: 0.14003798 | E9: 14 | F9: 1.4121391 | G9: 0.15644354 | H9: 22 | I9: 1.5713849 | J9: 0.12608281 | K9: 23 | L9: 1.4773318 | M9: 0.15830752 | N9: 2.2311266 | O9: 963.55631 | P9: 181.42333 | Q9: 636.93165 | R9: 253.51538 | S9: =Q9/O9 -> 0.66102172 | T9: =((((R9/Q9)^2+(P9/O9)^2))^0.5)*S9 -> 0.29105682
A10: 50 | B10: 45-56 | C10: 1.6308441 | D10: 0.1534416 | E10: 18 | F10: 1.6052969 | G10: 0.19704196 | H10: 21 | I10: 1.733699 | J10: 0.13461988 | K10: 19 | L10: 1.6552881 | M10: 0.17183341 | N10: 2.2390776 | O10: 1276.252 | P10: 201.27912 | Q10: 789.4704 | R10: 307.33119 | S10: =Q10/O10 -> 0.61858502 | T10: =((((R10/Q10)^2+(P10/O10)^2))^0.5)*S10 -> 0.2598188
A11: 65 | B11: 59-69 | C11: 1.8512713 | D11: 0.23361981 | E11: 12 | F11: 1.9138562 | G11: 0.2247748 | H11: 14 | I11: 1.8982122 | J11: 0.16915175 | K11: 17 | L11: 1.8902058 | M11: 0.20366154 | N11: 2.2417401 | O11: 1406.632 | P11: 254.03086 | Q11: 907.80631 | R11: 386.19868 | S11: =Q11/O11 -> 0.64537586 | T11: =((((R11/Q11)^2+(P11/O11)^2))^0.5)*S11 -> 0.29827015
A12: 80 | B12: 75-83 | C12: 2.1322697 | D12: 0.21130928 | E12: 17 | F12: 2.1202179 | G12: 0.18728534 | H12: 21 | I12: 2.1062617 | J12: 0.17231947 | K12: 21 | L12: 2.118723 | M12: 0.18644817 | N12: 2.2452971 | O12: 1443.9001 | P12: 278.88075 | Q12: 997.01105 | R12: 468.83687 | S12: =Q12/O12 -> 0.69049865 | T12: =((((R12/Q12)^2+(P12/O12)^2))^0.5)*S12 -> 0.3510237
A13: 100 | B13: 94-109 | C13: 2.2637892 | D13: 0.23908842 | E13: 20 | F13: 2.2076711 | G13: 0.14996311 | H13: 23 | I13: 2.2434776 | J13: 0.13406204 | K13: 20 | L13: 2.2368535 | M13: 0.1776783 | N13: 2.2601034 | O13: 1451.7953 | P13: 304.09216 | Q13: 1023.6805 | R13: 545.29784 | S13: =Q13/O13 -> 0.70511354 | T13: =((((R13/Q13)^2+(P13/O13)^2))^0.5)*S13 -> 0.4035967 | U13: 100
A14: 120 | B14: 110-130 | C14: 2.3781853 | D14: 0.20702751 | E14: 34 | F14: 2.3300542 | G14: 0.18748341 | H14: 40 | I14: 2.3426177 | J14: 0.18348688 | K14: 41 | L14: 2.3487634 | M14: 0.19141494 | N14: 2.2929019 | O14: 1427.7807 | P14: 365.13156 | Q14: 1025.6914 | R14: 672.39601 | S14: =Q14/O14 -> 0.7183816 | T14: =((((R14/Q14)^2+(P14/O14)^2))^0.5)*S14 -> 0.50550315
A15: 150 | B15: 145-151 | C15: 2.3737988 | D15: 0.18152239 | E15: 18 | F15: 2.3164321 | G15: 0.099569827 | H15: 22 | I15: 2.3841901 | J15: 0.15456893 | K15: 20 | L15: 2.3562281 | M15: 0.1471958 | N15: 2.3258876 | O15: 1384.2241 | P15: 422.30601 | Q15: 940.82724 | R15: 860.56447 | S15: =Q15/O15 -> 0.67967843 | T15: =((((R15/Q15)^2+(P15/O15)^2))^0.5)*S15 -> 0.65536408 | U15: 150
A16: 200 | B16: 194-222 | C16: 2.3356006 | D16: 0.17064714 | E16: 22 | F16: 2.375935 | G16: 0.1902501 | H16: 23 | I16: 2.3719581 | J16: 0.17202147 | K16: 22 | L16: 2.361385 | M16: 0.17629158 | N16: 2.3364391 | O16: 1283.4489 | P16: 584.69947 | Q16: 774.13298 | R16: 1262.9917 | S16: =Q16/O16 -> 0.6031662 | T16: =((((R16/Q16)^2+(P16/O16)^2))^0.5)*S16 -> 1.0217053 | U16: 200
A17: 280 | B17: 249-314 | C17: 2.3848653 | D17: 0.094154855 | E17: 14 | F17: 2.358587 | G17: 0.28757883 | H17: 6 | I17: 2.2983178 | J17: 0.10754061 | K17: 6 | L17: 2.3588286 | M17: 0.15723104 | N17: 2.3448228 | O17: 1191.7697 | P17: 447.09221 | Q17: 1099.6547 | R17: 1382.0338 | S17: =Q17/O17 -> 0.92270737 | T17: =((((R17/Q17)^2+(P17/O17)^2))^0.5)*S17 -> 1.2102093
A18: 330 | B18: 328-334 | C18: 2.3394136 | D18: 0.14626751 | E18: 17 | F18: 2.2833333 | G18: 0.13566584 | H18: 21 | I18: 2.3222698 | J18: 0.15485979 | K18: 20 | L18: 2.313197 | M18: 0.14498156 | N18: 2.3508204 | O18: 1463.5199 | P18: 885.47229 | Q18: 1269.8795 | R18: 1960.9857 | S18: =Q18/O18 -> 0.86768863 | T18: =((((R18/Q18)^2+(P18/O18)^2))^0.5)*S18 -> 1.4390834 | U18: 330
A19: 500 | B19: 498-503 | C19: 2.3468829 | D19: 0.17478037 | E19: 12 | F19: 2.3539139 | G19: 0.17846666 | H19: 14 | I19: 2.3793238 | J19: 0.21538714 | K19: 13 | L19: 2.3602205 | M19: 0.18596969 | N19: 2.3643285 | O19: 1527.0937 | P19: 1118.6495 | Q19: 1116.2752 | R19: 2437.2582 | S19: =Q19/O19 -> 0.73098017 | T19: =((((R19/Q19)^2+(P19/O19)^2))^0.5)*S19 -> 1.6834421 | U19: 500
A20: Notes: | S20: *to derive NSS fluxes for individual profiles to compare to UVP, use these factors x individual SS fluxes
A21: aAverage sample depth in the bin | S21: Table S1 has complete SS 234Th for each profile
A22: bDepth range of the samples included in the bin | S22: MULTIPPLY SS by 0.71 to get average NSS flux
A23: cStandard deviation
A24: dCruise average steady-state (SS) 234Th fluxes were calculated from all the SS 234Th fluxes computed for each station. The uncertainty corresponds to the standard deviation across all the SS 234Th flux estimates
A25: eNon-steady-state (NSS) 234Th fluxes were calculated from the depth-averaged 234Th activities of epochs 1 and 3 following Equation 4. The uncertainty was calculated by propagating the standard deviations of 234Th activity from epochs 1 and 3 through Equation 4 (see section 4c)

Sheet Table 2
A1: Table 2 | B1: POC/234Th ratios - cruise averages
B3: POC/234Th (μmol dpm-1)
B4: 1-5 μma | D4: 5-51 μma | F4: >51 μma,b
A5: Depth (m) | B5: average | C5: st dev | D5: average | E5: st dev | F5: average | G5: st dev
A6: 50 | B6: 2.9513423 | C6: 0.46721058 | D6: 5.3045247 | E6: 1.8998611 | F6: 2.1553316 | G6: 0.36065659
A7: 65 | B7: 2.9136 | C7: 0.42685697 | D7: 4.1984 | E7: 1.2575677 | F7: 2.1387 | G7: 0.37770511
A8: 80 | B8: 2.8746 | C8: 0.38720862 | D8: 3.0929 | E8: 0.74507961 | F8: 2.1207 | G8: 0.3941533
A9: 100 | B9: 2.8201275 | C9: 0.33544035 | D9: 1.6201527 | E9: 0.26358716 | F9: 2.0939907 | G9: 0.4149607
A10: 120 | B10: 2.4384 | C10: 0.31998392 | D10: 1.4145 | E10: 0.28378548 | F10: 1.9972 | G10: 0.44091386
A11: 150 | B11: 1.8530067 | C11: 0.27729122 | D11: 1.1169602 | E11: 0.28766857 | F11: 1.8483985 | G11: 0.47061703
A12: 200 | B12: 1.2967227 | C12: 0.2083468 | D12: 1.027063 | E12: 0.060003865 | F12: 2.1464336 | G12: 0.38327466
A13: 280 | B13: 1.0309 | C13: 0.13727464 | D13: 0.9653 | E13: 0.11663141 | F13: 2.3156 | G13: 0.64788636
A14: 330 | B14: 0.88711057 | C14: 0.10285475 | D14: 0.93978101 | E14: 0.15036842 | F14: 2.4368606 | G14: 0.83583047
A15: 500 | B15: 0.82167132 | C15: 0.097320994 | D15: 0.87680273 | E15: 0.15828164 | F15: 1.8273909 | G15: 0.50584342
A16: Notes:
A17: aPOC/234Th (C/Th) ratios for size-fractionated particles were measured at 50, 100, 150, 200, 330 and 500 m. Average C/Th at these depths were obtained from the arithmetic mean (± standard deviation). Values shown in italics and smaller font size are linearly interpolated (see section 4d)
A18: bSeven >51 μm samples (out of 70) were identified as outliers due to swimmer contamination (see details in section 3b) and, therefore, are excluded from the average

Sheet Table 3
A1: Table 3 | B1: POC fluxes - cruise averages
B3: POC flux-SS (mmol C m-2 d-1)a | D3: POC flux-NSS (mmol C m-2 d-1)b | F3: Average POC flux (mmol C m-2 d-1)c
B4: 5-51 μm | D4: 5-51 μm | F4: 5-51 μm
A5: Depth (m) | B5: average | C5: uncert | D5: average | E5: uncert | F5: average | G5: uncert
A6: 50 | B6: ='Table 2'!D6*'Table 1'!O10/1000 -> 6.7699104 | C6: ='Table 2'!D6*'Table 1'!O10/1000*SQRT(('Table 2'!E6/'Table 2'!D6)^2+('Table 1'!P10/'Table 1'!O10)^2) -> 2.6493659 | D6: ='Table 2'!D6*'Table 1'!Q10/1000 -> 4.1877652 | E6: ='Table 2'!D6*'Table 1'!Q10/1000*SQRT(('Table 2'!E6/'Table 2'!D6)^2+('Table 1'!R10/'Table 1'!Q10)^2) -> 2.2152548 | F6: =AVERAGE(B6,D6) -> 5.4788378 | G6: =SQRT((C6)^2+(E6)^2)/2 -> 1.7267378
A7: 65 | B7: ='Table 2'!D7*'Table 1'!O11/1000 -> 5.9056036 | C7: ='Table 2'!D7*'Table 1'!O11/1000*SQRT(('Table 2'!E7/'Table 2'!D7)^2+('Table 1'!P11/'Table 1'!O11)^2) -> 2.0655756 | D7: ='Table 2'!D7*'Table 1'!Q11/1000 -> 3.811334 | E7: ='Table 2'!D7*'Table 1'!Q11/1000*SQRT(('Table 2'!E7/'Table 2'!D7)^2+('Table 1'!R11/'Table 1'!Q11)^2) -> 1.9830043 | F7: =AVERAGE(B7,D7) -> 4.8584688 | G7: =SQRT((C7)^2+(E7)^2)/2 -> 1.4316868
A8: 80 | B8: ='Table 2'!D8*'Table 1'!O12/1000 -> 4.4658385 | C8: ='Table 2'!D8*'Table 1'!O12/1000*SQRT(('Table 2'!E8/'Table 2'!D8)^2+('Table 1'!P12/'Table 1'!O12)^2) -> 1.3789064 | D8: ='Table 2'!D8*'Table 1'!Q12/1000 -> 3.0836555 | E8: ='Table 2'!D8*'Table 1'!Q12/1000*SQRT(('Table 2'!E8/'Table 2'!D8)^2+('Table 1'!R12/'Table 1'!Q12)^2) -> 1.6292698 | F8: =AVERAGE(B8,D8) -> 3.774747 | G8: =SQRT((C8)^2+(E8)^2)/2 -> 1.067228
A9: 100 | B9: ='Table 2'!D9*'Table 1'!O13/1000 -> 2.3521301 | C9: ='Table 2'!D9*'Table 1'!O13/1000*SQRT(('Table 2'!E9/'Table 2'!D9)^2+('Table 1'!P13/'Table 1'!O13)^2) -> 0.62383429 | D9: ='Table 2'!D9*'Table 1'!Q13/1000 -> 1.6585187 | E9: ='Table 2'!D9*'Table 1'!Q13/1000*SQRT(('Table 2'!E9/'Table 2'!D9)^2+('Table 1'!R13/'Table 1'!Q13)^2) -> 0.92375292 | F9: =AVERAGE(B9,D9) -> 2.0053244 | G9: =SQRT((C9)^2+(E9)^2)/2 -> 0.55733488
A10: 120 | B10: ='Table 2'!D10*'Table 1'!O14/1000 -> 2.0195958 | C10: ='Table 2'!D10*'Table 1'!O14/1000*SQRT(('Table 2'!E10/'Table 2'!D10)^2+('Table 1'!P14/'Table 1'!O14)^2) -> 0.65644783 | D10: ='Table 2'!D10*'Table 1'!Q14/1000 -> 1.4508405 | E10: ='Table 2'!D10*'Table 1'!Q14/1000*SQRT(('Table 2'!E10/'Table 2'!D10)^2+('Table 1'!R14/'Table 1'!Q14)^2) -> 0.99464795 | F10: =AVERAGE(B10,D10) -> 1.7352182 | G10: =SQRT((C10)^2+(E10)^2)/2 -> 0.59587085
A11: 150 | B11: ='Table 2'!D11*'Table 1'!O15/1000 -> 1.5461232 | C11: ='Table 2'!D11*'Table 1'!O15/1000*SQRT(('Table 2'!E11/'Table 2'!D11)^2+('Table 1'!P15/'Table 1'!O15)^2) -> 0.61730172 | D11: ='Table 2'!D11*'Table 1'!Q15/1000 -> 1.0508666 | E11: ='Table 2'!D11*'Table 1'!Q15/1000*SQRT(('Table 2'!E11/'Table 2'!D11)^2+('Table 1'!R15/'Table 1'!Q15)^2) -> 0.9985921 | F11: =AVERAGE(B11,D11) -> 1.2984949 | G11: =SQRT((C11)^2+(E11)^2)/2 -> 0.58699395
A12: 200 | B12: ='Table 2'!D12*'Table 1'!O16/1000 -> 1.3181829 | C12: ='Table 2'!D12*'Table 1'!O16/1000*SQRT(('Table 2'!E12/'Table 2'!D12)^2+('Table 1'!P16/'Table 1'!O16)^2) -> 0.60544114 | D12: ='Table 2'!D12*'Table 1'!Q16/1000 -> 0.79508338 | E12: ='Table 2'!D12*'Table 1'!Q16/1000*SQRT(('Table 2'!E12/'Table 2'!D12)^2+('Table 1'!R16/'Table 1'!Q16)^2) -> 1.2980035 | F12: =AVERAGE(B12,D12) -> 1.0566331 | G12: =SQRT((C12)^2+(E12)^2)/2 -> 0.71613059
A13: 280 | B13: ='Table 2'!D13*'Table 1'!O17/1000 -> 1.1504153 | C13: ='Table 2'!D13*'Table 1'!O17/1000*SQRT(('Table 2'!E13/'Table 2'!D13)^2+('Table 1'!P17/'Table 1'!O17)^2) -> 0.45340936 | D13: ='Table 2'!D13*'Table 1'!Q17/1000 -> 1.0614967 | E13: ='Table 2'!D13*'Table 1'!Q17/1000*SQRT(('Table 2'!E13/'Table 2'!D13)^2+('Table 1'!R17/'Table 1'!Q17)^2) -> 1.340228 | F13: =AVERAGE(B13,D13) -> 1.105956 | G13: =SQRT((C13)^2+(E13)^2)/2 -> 0.70742336
A14: 330 | B14: ='Table 2'!D14*'Table 1'!O18/1000 -> 1.3753882 | C14: ='Table 2'!D14*'Table 1'!O18/1000*SQRT(('Table 2'!E14/'Table 2'!D14)^2+('Table 1'!P18/'Table 1'!O18)^2) -> 0.86075736 | D14: ='Table 2'!D14*'Table 1'!Q18/1000 -> 1.1934087 | E14: ='Table 2'!D14*'Table 1'!Q18/1000*SQRT(('Table 2'!E14/'Table 2'!D14)^2+('Table 1'!R18/'Table 1'!Q18)^2) -> 1.8527632 | F14: =AVERAGE(B14,D14) -> 1.2843984 | G14: =SQRT((C14)^2+(E14)^2)/2 -> 1.0214738
A15: 500 | B15: ='Table 2'!D15*'Table 1'!O19/1000 -> 1.3389599 | C15: ='Table 2'!D15*'Table 1'!O19/1000*SQRT(('Table 2'!E15/'Table 2'!D15)^2+('Table 1'!P19/'Table 1'!O19)^2) -> 1.0101789 | D15: ='Table 2'!D15*'Table 1'!Q19/1000 -> 0.97875317 | E15: ='Table 2'!D15*'Table 1'!Q19/1000*SQRT(('Table 2'!E15/'Table 2'!D15)^2+('Table 1'!R19/'Table 1'!Q19)^2) -> 2.1442863 | F15: =AVERAGE(B15,D15) -> 1.1588566 | G15: =SQRT((C15)^2+(E15)^2)/2 -> 1.1851609
A16: Notes:
A17: aPOC fluxes were calculated by multiplying the C/Th ratio in 5-51 μm particles (Table 2) by the cruise average steady-state 234Th flux (Table 1) at a given depth
A18: bPOC fluxes were calculated by multiplying the C/Th ratio in 5-51 μm particles (Table 2) by the non-steady-state 234Th flux (Table 1) at a given depth
A19: a,bPOC flux uncertainties were calculated by propagating the C/Th ratio and 234Th flux uncertainties
A20: cAverage POC flux was calculated averaging the SS and NSS POC flux estimates using the C/Th ratio in 5-51 μm particles. Uncertainties were calculated by propagating the uncertainties of the SS and NSS POC flux estimates

Sheet Table 4
A1: Table 4 | B1: Comparison of POC export fluxes at OSP
B3: 50 m | E3: 100 m | H3: 200 m | K3: 500 m | N3: Comments
A4: 234Th based | B4: (mmol C m-2 d-1) | E4: (mmol C m-2 d-1) | H4: (mmol C m-2 d-1) | K4: (mmol C m-2 d-1)
A5: This study | B5: ='[1]Table 3'!F6 -> 5.4788378 | C5: ± | D5: ='[1]Table 3'!G6 -> 1.7267378 | E5: ='[1]Table 3'!F9 -> 2.0053244 | F5: ± | G5: ='[1]Table 3'!G9 -> 0.55733488 | H5: ='[1]Table 3'!F12 -> 1.0566331 | I5: ± | J5: ='[1]Table 3'!G12 -> 0.71613059 | K5: ='[1]Table 3'!F15 -> 1.1588566 | L5: ± | M5: ='[1]Table 3'!G15 -> 1.1851609 | N5: Aug/Sept EXPORTS cruise, avg. 61 profiles; >5-51 μm C/Th (Table 3)
A6: Charette et al. (1999) | B6: *8.1 | C6: ± | D6: 3.4 | E6: --- | H6: --- | K6: --- | N6: August, single profile; value for 40 m; >1 μm C/Th
A7: Kawakami et al. (2010) | B7: --- | E7: 2.3 | F7: ± | G7: 0.5 | H7: --- | K7: --- | N7: October, single profile; >0.7 μm C/Th
A8: Mackinson et al. (2015) | B8: 4.1 | C8: ± | D8: 0.6 | E8: 3 | F8: ± | G8: 0.1 | H8: 2 | I8: ± | J8: 0.8 | K8: --- | N8: June 2011 and 2012; recalculated here from 3 profiles; >53 μm C/Th
A10: Trap based
A11: Wong et al. (2002) | B11: 10.4 | C11: ± | D11: 3.1 | E11: 3.9 | F11: ± | G11: 2.5 | H11: 4 | I11: ± | J11: 1.2 | K11: 1.9 | L11: ± | M11: 0.4 | N11: July-Sept avg; Wong et al. and includes unpubished data; 7 deployments
A12: Timothy et al. (2013) | B12: --- | E12: --- | H12: 1.3 | J12: nd | K12: --- | N12: Deep moored time-series traps - annual average
A13: Estapa et al. (2020) | B13: --- | E13: 1.38 | F13: ± | G13: 0.77 | H13: 0.76 | I13: ± | J13: 0.24 | K13: 0.86 | L13: ± | M13: 0.43 | N13: Aug/Sept EXPORTS cruise, avg. 3 casts
A14: Mackinson et al. (2015) | B14: 11.8 | C14: ± | D14: 1.7 | E14: 6.2 | F14: ± | G14: 0.3 | H14: 6.8 | I14: ± | J14: 1.8 | N14: June 2011 and 2012, avg. 2 deployments, no poison
A16: Notes:
A17: *POC flux estimated at 40 m considered base of Ez

Sheet Table S1
A1: Table S1 | B1: Thorium-234 results and POC fluxes for each cast | T1: NSS/SS= | U1: ='Table 1'!W7 -> 0.70705883 | V1: ='Table 1'!X7 -> 0.091652581 | W1: Use this from Table 1 mean and st dev for correction below
W2: Added this uncertainty on NSS term to NSS POC flux uncertainty
N3: 1D SS model | R3: SS | T3: NSS = SS*0.71
A4: Internala | B4: bottle | C4: Station | H4: CTD | I4: collection | K4: 238U | L4: 234Th | N4: 234Th flux @zb | P4: POC/234Thc | R4: SS POC fluxd | T4: NSS POC fluxe
A5: SR# | B5: depth | C5: # | D5: CTD# | E5: Epoch | F5: Latitude | G5: Longitude | H5: Niskin | I5: date | J5: time | K5: dpm L-1 | L5: dpm L-1 | M5: uncert | N5: dpm m-2 d-1 | O5: uncert | P5: μmol dpm-1 | Q5: st dev | R5: mmol C m-2 d-1 | S5: uncert | T5: mmol C m-2 d-1 | U5: uncert
A6: 6 | B6: 5.241 | C6: SS1 | D6: 1 | E6: 1 | F6: 50.086 | G6: -145.05 | H6: 14 | I6: 43326.336 | J6: 43326.336 | K6: 2.224959 | L6: 1.4255163 | M6: 0.069284611 | N6: 299.321 | O6: 25.940994 | P6: 5.3045247 | Q6: 1.8998611 | R6: 1.5877556 | S6: 0.58508008 | T6: =R6*U$1 -> 1.1226366 | U6: =((((S6/R6)^2+(V$1/U$1)^2))^0.5)*T6 -> 0.43853479
A7: 7 | B7: 20.796 | C7: SS1 | D7: 1 | E7: 1 | F7: 50.086 | G7: -145.05 | H7: 13 | I7: 43326.336 | J7: 43326.336 | K7: 2.224959 | L7: 1.1867027 | M7: 0.063296788 | N7: 732.41408 | O7: 37.014455 | P7: 5.3045247 | Q7: 1.8998611 | R7: 3.8851086 | S7: 1.4052692 | T7: =R7*U$1 -> 2.7470003 | U7: =((((S7/R7)^2+(V$1/U$1)^2))^0.5)*T7 -> 1.0554857
A8: 8 | B8: 34.249 | C8: SS1 | D8: 1 | E8: 1 | F8: 50.086 | G8: -145.05 | H8: 12 | I8: 43326.336 | J8: 43326.336 | K8: 2.2323474 | L8: 1.5618981 | M8: 0.081239356 | N8: 999.38468 | O8: 49.158344 | P8: 5.3045247 | Q8: 1.8998611 | R8: 5.3012607 | S8: 1.9165146 | T8: =R8*U$1 -> 3.7483032 | U8: =((((S8/R8)^2+(V$1/U$1)^2))^0.5)*T8 -> 1.439562
A9: 9 | B9: 48.487 | C9: SS1 | D9: 1 | E9: 1 | F9: 50.086 | G9: -145.05 | H9: 11 | I9: 43326.336 | J9: 43326.336 | K9: 2.2353342 | L9: 1.7369509 | M9: 0.089650296 | N9: 1207.7508 | O9: 61.817437 | P9: 5.3045247 | Q9: 1.8998611 | R9: 6.406544 | S9: 2.3178711 | T9: =R9*U$1 -> 4.5298035 | U9: =((((S9/R9)^2+(V$1/U$1)^2))^0.5)*T9 -> 1.7408834
A10: 10 | B10: 63.323 | C10: SS1 | D10: 1 | E10: 1 | F10: 50.086 | G10: -145.05 | H10: 10 | I10: 43326.336 | J10: 43326.336 | K10: 2.2395 | L10: 1.9128519 | M10: 0.0860055 | N10: 1351.7012 | O10: 72.511625 | P10: 4.3219949 | Q10: 1.3229211 | R10: 5.8420457 | S10: 1.8154488 | T10: =R10*U$1 -> 4.13067 | U10: =((((S10/R10)^2+(V$1/U$1)^2))^0.5)*T10 -> 1.3908264
A11: 11 | B11: 79.133 | C11: SS1 | D11: 1 | E11: 1 | F11: 50.086 | G11: -145.05 | H11: 9 | I11: 43326.336 | J11: 43326.336 | K11: 2.2433514 | L11: 2.2611901 | M11: 0.09697624 | N11: 1342.7043 | O11: 87.464954 | P11: 3.1567979 | Q11: 0.77117133 | R11: 4.2386461 | S11: 1.0716359 | T11: =R11*U$1 -> 2.9969721 | U11: =((((S11/R11)^2+(V$1/U$1)^2))^0.5)*T11 -> 0.85149443
A12: 12 | B12: 98.396 | C12: SS1 | D12: 1 | E12: 1 | F12: 50.086 | G12: -145.05 | H12: 8 | I12: 43326.336 | J12: 43326.336 | K12: 2.246181 | L12: 2.4037463 | M12: 0.1034619 | N12: 1276.4685 | O12: 97.681632 | P12: 1.7371148 | Q12: 0.29355509 | R12: 2.2173723 | S12: 0.41134314 | T12: =R12*U$1 -> 1.5678126 | U12: =((((S12/R12)^2+(V$1/U$1)^2))^0.5)*T12 -> 0.35481219
A13: 13 | B13: 108.366 | C13: SS1 | D13: 1 | E13: 1 | F13: 50.086 | G13: -145.05 | H13: 7 | I13: 43326.336 | J13: 43326.336 | K13: 2.2762848 | L13: 2.5685619 | M13: 0.11780114 | N13: 1174.4084 | O13: 105.98954 | P13: 1.5320034 | Q13: 0.27354886 | R13: 1.7991976 | S13: 0.35996226 | T13: =R13*U$1 -> 1.2721386 | U13: =((((S13/R13)^2+(V$1/U$1)^2))^0.5)*T13 -> 0.30326556
A14: 14 | B14: 122.679 | C14: SS1 | D14: 1 | E14: 1 | F14: 50.086 | G14: -145.05 | H14: 6 | I14: 43326.336 | J14: 43326.336 | K14: 2.3054454 | L14: 2.3671574 | M14: 0.1022485 | N14: 1137.9266 | O14: 122.01406 | P14: 1.3874421 | Q14: 0.28540803 | R14: 1.5788072 | S14: 0.3662458 | T14: =R14*U$1 -> 1.1163096 | U14: =((((S14/R14)^2+(V$1/U$1)^2))^0.5)*T14 -> 0.29664372
A15: 15 | B15: 149.476 | C15: SS1 | D15: 1 | E15: 1 | F15: 50.086 | G15: -145.05 | H15: 5 | I15: 43326.336 | J15: 43326.336 | K15: 2.3249382 | L15: 2.1716329 | M15: 0.09741999 | N15: 1304.7103 | O15: 161.61764 | P15: 1.1167924 | Q15: 0.28650412 | R15: 1.4570905 | S15: 0.41509991 | T15: =R15*U$1 -> 1.0302487 | U15: =((((S15/R15)^2+(V$1/U$1)^2))^0.5)*T15 -> 0.32245441
A16: 16 | B16: 198.334 | C16: SS1 | D16: 1 | E16: 1 | F16: 50.086 | G16: -145.05 | H16: 4 | I16: 43326.336 | J16: 43326.336 | K16: 2.3371998 | L16: 2.3540726 | M16: 0.097988964 | N16: 1260.1311 | O16: 305.19832 | P16: 1.0296988 | Q16: 0.067089008 | R16: 1.2975555 | S16: 0.32543508 | T16: =R16*U$1 -> 0.91744807 | U16: =((((S16/R16)^2+(V$1/U$1)^2))^0.5)*T16 -> 0.259017
A17: 17 | B17: 333.208 | C17: SS1 | D17: 1 | E17: 1 | F17: 50.086 | G17: -145.05 | H17: 3 | I17: 43326.336 | J17: 43326.336 | K17: 2.3516622 | L17: 2.3924466 | M17: 0.098376186 | N17: 1081.4861 | O17: 528.04364 | P17: 0.9287168 | Q17: 0.14905734 | R17: 1.0043943 | S17: 0.51621861 | T17: =R17*U$1 -> 0.71016585 | U17: =((((S17/R17)^2+(V$1/U$1)^2))^0.5)*T17 -> 0.37642654
... A64: 57 | B64: 194.914 | C64: SS5 | D64: 5 | E64: 1 | F64: 50.243 | G64: -145.112 | H64: 3 | I64: 43326.756 | J64: 43326.756 | K64: 2.3368697 | L64: 2.1488117 | M64: 0.088563999 | N64: 1599.2738 | O64: 289.97923 | P64: 1.0358548 | Q64: 0.081596823 | R64: 1.6566154 | S64: 0.32749822 | T64: =R64*U$1 -> 1.1713245 | U64: =((((S64/R64)^2+(V$1/U$1)^2))^0.5)*T64 -> 0.27689989
A65: 66 avg | B65: 331.846 | C65: SS5 | D65: 5 | E65: 1 | F65: 50.243 | G65: -145.112 | H65: 2 | I65: 43326.756 | J65: 43326.756 | K65: 2.3511592 | L65: 2.4148491 | M65: 0.066553703 | N65: 1473.863 | O65: 318.21687 | P65: 0.9292616 | Q65: 0.14899164 | R65: 1.3696043 | S65: 0.36832549 | T65: =R65*U$1 -> 0.96839078 | U65: =((((S65/R65)^2+(V$1/U$1)^2))^0.5)*T65 -> 0.2891018
A66: 77 | B66: 4.959 | C66: SS6 | D66: 6 | E66: 1 | F66: 50.206 | G66: -145.015 | H66: 13 | I66: 43326.826 | J66: 43326.826 | K66: 2.2250612 | L66: 1.5481761 | M66: 0.076278165 | N66: 242.56148 | O66: 27.33425 | P66: 5.3045247 | Q66: 1.8998611 | R66: 1.2866734 | S66: 0.48310534 | T66: =R66*U$1 -> 0.90975376 | U66: =((((S66/R66)^2+(V$1/U$1)^2))^0.5)*T66 -> 0.36136729
A67: 76 | B67: 19.961 | C67: SS6 | D67: 6 | E67: 1 | F67: 50.206 | G67: -145.015 | H67: 12 | I67: 43326.826 | J67: 43326.826 | K67: 2.2250769 | L67: 1.2827634 | M67: 0.063010638 | N67: 653.61495 | O67: 38.764153 | P67: 5.3045247 | Q67: 1.8998611 | R67: 3.4671166 | S67: 1.2586872 | T67: =R67*U$1 -> 2.4514554 | U67: =((((S67/R67)^2+(V$1/U$1)^2))^0.5)*T67 -> 0.94499586
A68: 75 | B68: 35.294 | C68: SS6 | D68: 6 | E68: 1 | F68: 50.206 | G68: -145.015 | H68: 11 | I68: 43326.826 | J68: 43326.826 | K68: 2.2305396 | L68: 1.58094 | M68: 0.077916596 | N68: 940.03614 | O68: 51.796933 | P68: 5.3045247 | Q68: 1.8998611 | R68: 4.9864449 | S68: 1.8069496 | T68: =R68*U$1 -> 3.5257099 | U68: =((((S68/R68)^2+(V$1/U$1)^2))^0.5)*T68 -> 1.3569008
A69: 74 | B69: 50.623 | C69: SS6 | D69: 6 | E69: 1 | F69: 50.206 | G69: -145.015 | H69: 10 | I69: 43326.826 | J69: 43326.826 | K69: 2.2362774 | L69: 1.8274674 | M69: 0.088892538 | N69: 1197.3404 | O69: 76.244285 | P69: 5.2579849 | Q69: 1.8704476 | R69: 6.295598 | S69: 2.2751603 | T69: =R69*U$1 -> 4.4513582 | U69: =((((S69/R69)^2+(V$1/U$1)^2))^0.5)*T69 -> 1.7090244
A70: 73 | B70: 79.063 | C70: SS6 | D70: 6 | E70: 1 | F70: 50.206 | G70: -145.015 | H70: 8 | I70: 43326.826 | J70: 43326.826 | K70: 2.2401288 | L70: 1.7650212 | M70: 0.077266075 | N70: 1510.2482 | O70: 91.666536 | P70: 3.1619569 | Q70: 0.77329682 | R70: 4.7753397 | S70: 1.2033001 | T70: =R70*U$1 -> 3.3764461 | U70: =((((S70/R70)^2+(V$1/U$1)^2))^0.5)*T70 -> 0.95677811
A71: 72 | B71: 96.423 | C71: SS6 | D71: 6 | E71: 1 | F71: 50.206 | G71: -145.015 | H71: 7 | I71: 43326.826 | J71: 43326.826 | K71: 2.2547563 | L71: 2.1810476 | M71: 0.091611912 | N71: 1542.6206 | O71: 100.10815 | P71: 1.8825249 | Q71: 0.33264684 | R71: 2.9040217 | S71: 0.54665934 | T71: =R71*U$1 -> 2.0533142 | U71: =((((S71/R71)^2+(V$1/U$1)^2))^0.5)*T71 -> 0.469297
A72: 71 | B72: 109.605 | C72: SS6 | D72: 6 | E72: 1 | F72: 50.206 | G72: -145.015 | H72: 6 | I72: 43326.826 | J72: 43326.826 | K72: 2.2755617 | L72: 2.0929375 | M72: 0.09356198 | N72: 1620.2965 | O72: 107.72777 | P72: 1.5194895 | Q72: 0.27488581 | R72: 2.4620234 | S72: 0.47452382 | T72: =R72*U$1 -> 1.7407954 | U72: =((((S72/R72)^2+(V$1/U$1)^2))^0.5)*T72 -> 0.40433828
A73: 70 | B73: 126.001 | C73: SS6 | D73: 6 | E73: 1 | F73: 50.206 | G73: -145.015 | H73: 5 | I73: 43326.826 | J73: 43326.826 | K73: 2.3041171 | L73: 2.3973445 | M73: 0.098302978 | N73: 1571.0008 | O73: 119.61241 | P73: 1.3538899 | Q73: 0.28703806 | R73: 2.1269622 | S73: 0.47913404 | T73: =R73*U$1 -> 1.5038874 | U73: =((((S73/R73)^2+(V$1/U$1)^2))^0.5)*T73 -> 0.39085977
A74: 69 | B74: 146.376 | C74: SS6 | D74: 6 | E74: 1 | F74: 50.206 | G74: -145.015 | H74: 4 | I74: 43326.826 | J74: 43326.826 | K74: 2.327029 | L74: 1.9982531 | M74: 0.079925403 | N74: 1902.1263 | O74: 144.17638 | P74: 1.1481024 | Q74: 0.28778481 | R74: 2.1838357 | S74: 0.57188288 | T74: =R74*U$1 -> 1.5441003 | U74: =((((S74/R74)^2+(V$1/U$1)^2))^0.5)*T74 -> 0.45118126
A75: 68 | B75: 196.039 | C75: SS6 | D75: 6 | E75: 1 | F75: 50.206 | G75: -145.015 | H75: 3 | I75: 43326.826 | J75: 43326.826 | K75: 2.3371291 | L75: 2.3214375 | M75: 0.090763649 | N75: 1943.3081 | O75: 278.44019 | P75: 1.0338298 | Q75: 0.076806009 | R75: 2.0090499 | S75: 0.32425471 | T75: =R75*U$1 -> 1.4205164 | U75: =((((S75/R75)^2+(V$1/U$1)^2))^0.5)*T75 -> 0.29405609
A76: 67 | B76: 328.884 | C76: SS6 | D76: 6 | E76: 1 | F76: 50.206 | G76: -145.015 | H76: 2 | I76: 43326.826 | J76: 43326.826 | K76: 2.3508133 | L76: 2.0792679 | M76: 0.082729552 | N76: 2462.0444 | O76: 320.16452 | P76: 0.93978101 | Q76: 0.15036842 | R76: 2.3137826 | S76: 0.47706363 | T76: =R76*U$1 -> 1.6359804 | U76: =((((S76/R76)^2+(V$1/U$1)^2))^0.5)*T76 -> 0.39843522
A77: 78 | B77: 6.233 | C77: SS7 | D77: 9 | E77: 1 | F77: 50.144 | G77: -145.07 | H77: 13 | I77: 43327.215 | J77: 43327.215 | K77: 2.2249983 | L77: 1.2355027 | M77: 0.060351863 | N77: 381.62037 | O77: 23.276 | P77: 5.3045247 | Q77: 1.8998611 | R77: 2.0243147 | S77: 0.73546354 | T77: =R77*U$1 -> 1.4313096 | U77: =((((S77/R77)^2+(V$1/U$1)^2))^0.5)*T77 -> 0.5521226
... A188: 312 | B188: 124.89 | C188: SS11 | D188: 22 | E188: 1 | F188: 50.046 | G188: -145.03 | H188: 9 | I188: 43329.26 | J188: 43329.26 | K188: 2.3163708 | L188: 2.0622441 | M188: 0.10289271 | N188: 1570.9677 | O188: 125.91342 | P188: 1.365111 | Q188: 0.28653998 | R188: 2.1445452 | S188: 0.48184571 | T188: =R188*U$1 -> 1.5163196 | U188: =((((S188/R188)^2+(V$1/U$1)^2))^0.5)*T188 -> 0.39332559
A189: 311 avg | B189: 150.22 | C189: SS11 | D189: 22 | E189: 1 | F189: 50.046 | G189: -145.03 | H189: 7 | I189: 43329.26 | J189: 43329.26 | K189: 2.3322401 | L189: 2.3391754 | M189: 0.020538255 | N189: 1563.8603 | O189: 127.66047 | P189: 1.1169602 | Q189: 0.28766857 | R189: 1.7467698 | S189: 0.47193063 | T189: =R189*U$1 -> 1.235069 | U189: =((((S189/R189)^2+(V$1/U$1)^2))^0.5)*T189 -> 0.37010117
A190: 310 | B190: 196.156 | C190: SS11 | D190: 22 | E190: 1 | F190: 50.046 | G190: -145.03 | H190: 5 | I190: 43329.26 | J190: 43329.26 | K190: 2.3373256 | L190: 2.1332461 | M190: 0.091561719 | N190: 2089.0094 | O190: 267.97419 | P190: 1.0336192 | Q190: 0.076308806 | R190: 2.1592402 | S190: 0.31957976 | T190: =R190*U$1 -> 1.5267098 | U190: =((((S190/R190)^2+(V$1/U$1)^2))^0.5)*T190 -> 0.30037155
A191: 309 | B191: 329.167 | C191: SS11 | D191: 22 | E191: 1 | F191: 50.046 | G191: -145.03 | H191: 3 | I191: 43329.26 | J191: 43329.26 | K191: 2.350271 | L191: 2.3329168 | M191: 0.086731275 | N191: 2164.6346 | O191: 463.31344 | P191: 0.93978101 | Q191: 0.15036842 | R191: 2.0342825 | S191: 0.54362682 | T191: =R191*U$1 -> 1.4383574 | U191: =((((S191/R191)^2+(V$1/U$1)^2))^0.5)*T191 -> 0.42720908
A192: 308 | B192: 499.199 | C192: SS11 | D192: 22 | E192: 1 | F192: 50.046 | G192: -145.03 | H192: 1 | I192: 43329.26 | J192: 43329.26 | K192: 2.3645998 | L192: 2.0958511 | M192: 0.091606847 | N192: 2821.7412 | O192: 514.6147 | P192: 0.87680273 | Q192: 0.15828164 | R192: 2.4741103 | S192: 0.63488084 | T192: =R192*U$1 -> 1.7493416 | U192: =((((S192/R192)^2+(V$1/U$1)^2))^0.5)*T192 -> 0.50292044
A193: 321 | B193: 6.024 | C193: SS9 | D193: 23 | E193: 1 | F193: 50.019 | G193: -145.182 | H193: 17 | I193: 43329.719 | J193: 43329.719 | K193: 2.2237486 | L193: 1.3596971 | M193: 0.066473289 | N193: 322.86517 | O193: 24.838695 | P193: 5.3045247 | Q193: 1.8998611 | R193: 1.7126463 | S193: 0.6273901 | T193: =R193*U$1 -> 1.2109417 | U193: =((((S193/R193)^2+(V$1/U$1)^2))^0.5)*T193 -> 0.47055453
A194: 322 | B194: 19.961 | C194: SS9 | D194: 23 | E194: 1 | F194: 50.019 | G194: -145.182 | H194: 16 | I194: 43329.719 | J194: 43329.719 | K194: 2.2240315 | L194: 1.488399 | M194: 0.064762365 | N194: 627.73453 | O194: 36.569431 | P194: 5.3045247 | Q194: 1.8998611 | R194: 3.3298333 | S194: 1.2082816 | T194: =R194*U$1 -> 2.354388 | U194: =((((S194/R194)^2+(V$1/U$1)^2))^0.5)*T194 -> 0.90720052
A195: 323 | B195: 34.844 | C195: SS9 | D195: 23 | E195: 1 | F195: 50.019 | G195: -145.182 | H195: 15 | I195: 43329.719 | J195: 43329.719 | K195: 2.2378258 | L195: 1.3116012 | M195: 0.065006485 | N195: 1028.0537 | O195: 46.116339 | P195: 5.3045247 | Q195: 1.8998611 | R195: 5.4533363 | S195: 1.9684188 | T195: =R195*U$1 -> 3.8558296 | U195: =((((S195/R195)^2+(V$1/U$1)^2))^0.5)*T195 -> 1.4788123
A196: 324 | B196: 50.017 | C196: SS9 | D196: 23 | E196: 1 | F196: 50.019 | G196: -145.182 | H196: 14 | I196: 43329.719 | J196: 43329.719 | K196: 2.2414178 | L196: 1.7712987 | M196: 0.071842677 | N196: 1237.9749 | O196: 56.176749 | P196: 5.3045247 | Q196: 1.8998611 | R196: 6.5668686 | S196: 2.3707827 | T196: =R196*U$1 -> 4.6431625 | U196: =((((S196/R196)^2+(V$1/U$1)^2))^0.5)*T196 -> 1.7810593
...

Sheet Table S2
A1: Table S2 | B1: Comparison of two methods to obtain mean C/Th ratios
B4: POC/234Th (μmol dpm-1)
B5: Small (1-5 μm) | G5: Mid (5-51 μm) | L5: Large (>51 μm)c
B6: slopea | E6: arithmetic mean | G6: slopeb | J6: arithmetic mean | L6: sloped | O6: arithmetic mean
A7: Depth (m) | B7: mean | C7: st err | D7: R2 | E7: mean | F7: st dev | G7: mean | H7: st err | I7: R2 | J7: mean | K7: st dev | L7: mean | M7: st err | N7: R2 | O7: mean | P7: st dev
A8: 50 | B8: 2.9349 | C8: 0.0781 | D8: 0.9137 | E8: 2.9513423 | F8: 0.46721058 | G8: 5.7626 | H8: 0.5533 | I8: 0.597 | J8: 5.3045247 | K8: 1.8998611 | L8: 1.956 | M8: 0.0539 | N8: 0.8065 | O8: 2.1553316 | P8: 0.36065659
A9: 100 | B9: 2.9349 | C9: 0.0781 | D9: 0.9137 | E9: 2.8201275 | F9: 0.33544035 | G9: 1.6106 | H9: 0.0741 | I9: 0.7004 | J9: 1.6201527 | K9: 0.26358716 | L9: 1.956 | M9: 0.0539 | N9: 0.8065 | O9: 2.0939907 | P9: 0.4149607
A10: 150 | E10: 1.8530067 | F10: 0.27729122 | G10: 1.0002 | H10: 0.0209 | I10: 0.8926 | J10: 1.1169602 | K10: 0.28766857 | L10: 1.956 | M10: 0.0539 | N10: 0.8065 | O10: 1.8483985 | P10: 0.47061703
A11: 200 | E11: 1.2967227 | F11: 0.2083468 | G11: 1.0002 | H11: 0.0209 | I11: 0.8926 | J11: 1.027063 | K11: 0.060003865 | L11: 1.956 | M11: 0.0539 | N11: 0.8065 | O11: 2.1464336 | P11: 0.38327466
A12: 330 | B12: 0.8471 | C12: 0.0218 | D12: 0.6124 | E12: 0.88711057 | F12: 0.10285475 | G12: 1.0002 | H12: 0.0209 | I12: 0.8926 | J12: 0.93978101 | K12: 0.15036842 | L12: 1.956 | M12: 0.0539 | N12: 0.8065 | O12: 2.4368606 | P12: 0.83583047
A13: 500 | B13: 0.8471 | C13: 0.0218 | D13: 0.6124 | E13: 0.82167132 | F13: 0.097320994 | G13: 1.0002 | H13: 0.0209 | I13: 0.8926 | J13: 0.87680273 | K13: 0.15828164 | L13: 1.956 | M13: 0.0539 | N13: 0.8065 | O13: 1.8273909 | P13: 0.50584342
A14: Notes:
A15: Mean POC/234Th (C/Th) ratios in size-fractionated particles combining all in situ pump casts (n = 12) obtained by using two methods: 1) slope (± standard error) from the linear relationships between POC concentrations and 234Th activities measured at either a single depth or a combination of depths and setting the intercept to zero, 2) arithmetic mean (± standard deviation) at each sampled depth. Both methods provide comparable results within uncertainties
A16: aFor small particles, mean C/Th ratios (slope) were calculated from POC vs. 234Th relationships measured at 50-100 m and 330-500 m. No relationships were found at 150 m and 200 m
A17: bFor mid-sized particles, mean C/Th ratios (slope) were calculated from POC vs. 234Th relationships measured at 50 m, 100 m and 150-500 m
A18: cSeven samples (out of 70) were identified as outliers due to swimmer contamination (see details in section 3b) and, therefore, were excluded from this analysis
A19: dFor large particles, the mean C/Th ratio (slope) was calculated from the POC vs. 234Th relationship combining data from all depths (50-500 m)

Sheet Table S3
A1: Table S3 | B1: Sensitivity of cruise average POC fluxes to choice of SS vs NSS model and C/Th ratios
B3: POC flux-SS (mmol C m-2 d-1)a | H3: POC flux-NSS (mmol C m-2 d-1)b | N3: Average POC flux (mmol C m-2 d-1)c
B4: 1-5 μm | D4: 5-51 μm | F4: >51 μm | H4: 1-5 μm | J4: 5-51 μm | L4: >51 μm | N4: 1-5 μm | P4: 5-51 μm | R4: >51 μm
A5: Depth (m) | B5: average | C5: uncert | D5: average | E5: uncert | F5: average | G5: uncert | H5: average | I5: uncert | J5: average | K5: uncert | L5: average | M5: uncert | N5: average | O5: uncert | P5: average | Q5: uncert | R5: average | S5: uncert
A6: 50 | B6: ='Table 2'!B6*'Table 1'!O10/1000 -> 3.7666566 | C6: ='Table 2'!B6*'Table 1'!O10/1000*SQRT(('Table 2'!C6/'Table 2'!B6)^2+('Table 1'!P10/'Table 1'!O10)^2) -> 0.84168627 | D6: ='Table 3'!B6 -> 6.7699104 | E6: ='Table 3'!C6 -> 2.6493659 | F6: ='Table 2'!F6*'Table 1'!O10/1000 -> 2.7507464 | G6: ='Table 2'!F6*'Table 1'!O10/1000*SQRT(('Table 2'!G6/'Table 2'!F6)^2+('Table 1'!P10/'Table 1'!O10)^2) -> 0.63250953 | H6: ='Table 2'!B6*'Table 1'!Q10/1000 -> 2.3299974 | I6: ='Table 2'!B6*'Table 1'!Q10/1000*SQRT(('Table 2'!C6/'Table 2'!B6)^2+('Table 1'!R10/'Table 1'!Q10)^2) -> 0.97916814 | J6: ='Table 3'!D6 -> 4.1877652 | K6: ='Table 3'!E6 -> 2.2152548 | L6: ='Table 2'!F6*'Table 1'!Q10/1000 -> 1.7015705 | M6: ='Table 2'!F6*'Table 1'!Q10/1000*SQRT(('Table 2'!G6/'Table 2'!F6)^2+('Table 1'!R10/'Table 1'!Q10)^2) -> 0.7210024 | N6: =AVERAGE(B6,H6) -> 3.048327 | O6: =SQRT((C6)^2+(I6)^2)/2 -> 0.64560166 | P6: =AVERAGE(D6,J6) -> 5.4788378 | Q6: =SQRT((E6)^2+(K6)^2)/2 -> 1.7267378 | R6: =AVERAGE(F6,L6) -> 2.2261585 | S6: =SQRT((G6)^2+(M6)^2)/2 -> 0.47956042 | T6: =H6/B6 -> 0.61858502
A7: 65 | B7: ='Table 2'!B7*'Table 1'!O11/1000 -> 4.0983629 | C7: ='Table 2'!B7*'Table 1'!O11/1000*SQRT(('Table 2'!C7/'Table 2'!B7)^2+('Table 1'!P11/'Table 1'!O11)^2) -> 0.95306379 | D7: ='Table 3'!B7 -> 5.9056036 | E7: ='Table 3'!C7 -> 2.0655756 | F7: ='Table 2'!F7*'Table 1'!O11/1000 -> 3.0083638 | G7: ='Table 2'!F7*'Table 1'!O11/1000*SQRT(('Table 2'!G7/'Table 2'!F7)^2+('Table 1'!P11/'Table 1'!O11)^2) -> 0.75989579 | H7: ='Table 2'!B7*'Table 1'!Q11/1000 -> 2.6449845 | I7: ='Table 2'!B7*'Table 1'!Q11/1000*SQRT(('Table 2'!C7/'Table 2'!B7)^2+('Table 1'!R11/'Table 1'!Q11)^2) -> 1.1900832 | J7: ='Table 3'!D7 -> 3.811334 | K7: ='Table 3'!E7 -> 1.9830043 | L7: ='Table 2'!F7*'Table 1'!Q11/1000 -> 1.9415254 | M7: ='Table 2'!F7*'Table 1'!Q11/1000*SQRT(('Table 2'!G7/'Table 2'!F7)^2+('Table 1'!R11/'Table 1'!Q11)^2) -> 0.89430637 | N7: =AVERAGE(B7,H7) -> 3.3716737 | O7: =SQRT((C7)^2+(I7)^2)/2 -> 0.76233664 | P7: =AVERAGE(D7,J7) -> 4.8584688 | Q7: =SQRT((E7)^2+(K7)^2)/2 -> 1.4316868 | R7: =AVERAGE(F7,L7) -> 2.4749446 | S7: =SQRT((G7)^2+(M7)^2)/2 -> 0.58677625 | T7: =H7/B7 -> 0.64537586
A8: 80 | B8: ='Table 2'!B8*'Table 1'!O12/1000 -> 4.1506351 | C8: ='Table 2'!B8*'Table 1'!O12/1000*SQRT(('Table 2'!C8/'Table 2'!B8)^2+('Table 1'!P12/'Table 1'!O12)^2) -> 0.97737302 | D8: ='Table 3'!B8 -> 4.4658385 | E8: ='Table 3'!C8 -> 1.3789064 | F8: ='Table 2'!F8*'Table 1'!O12/1000 -> 3.0620789 | G8: ='Table 2'!F8*'Table 1'!O12/1000*SQRT(('Table 2'!G8/'Table 2'!F8)^2+('Table 1'!P12/'Table 1'!O12)^2) -> 0.82077752 | H8: ='Table 2'!B8*'Table 1'!Q12/1000 -> 2.866008 | I8: ='Table 2'!B8*'Table 1'!Q12/1000*SQRT(('Table 2'!C8/'Table 2'!B8)^2+('Table 1'!R12/'Table 1'!Q12)^2) -> 1.4019203 | J8: ='Table 3'!D8 -> 3.0836555 | K8: ='Table 3'!E8 -> 1.6292698 | L8: ='Table 2'!F8*'Table 1'!Q12/1000 -> 2.1143613 | M8: ='Table 2'!F8*'Table 1'!Q12/1000*SQRT(('Table 2'!G8/'Table 2'!F8)^2+('Table 1'!R12/'Table 1'!Q12)^2) -> 1.0691058 | N8: =AVERAGE(B8,H8) -> 3.5083216 | O8: =SQRT((C8)^2+(I8)^2)/2 -> 0.8544938 | P8: =AVERAGE(D8,J8) -> 3.774747 | Q8: =SQRT((E8)^2+(K8)^2)/2 -> 1.067228 | R8: =AVERAGE(F8,L8) -> 2.5882201 | S8: =SQRT((G8)^2+(M8)^2)/2 -> 0.67391818 | T8: =H8/B8 -> 0.69049865
A9: 100 | B9: ='Table 2'!B9*'Table 1'!O13/1000 -> 4.0942479 | C9: ='Table 2'!B9*'Table 1'!O13/1000*SQRT(('Table 2'!C9/'Table 2'!B9)^2+('Table 1'!P13/'Table 1'!O13)^2) -> 0.98620541 | D9: ='Table 3'!B9 -> 2.3521301 | E9: ='Table 3'!C9 -> 0.62383429 | F9: ='Table 2'!F9*'Table 1'!O13/1000 -> 3.0400459 | G9: ='Table 2'!F9*'Table 1'!O13/1000*SQRT(('Table 2'!G9/'Table 2'!F9)^2+('Table 1'!P13/'Table 1'!O13)^2) -> 0.8765858 | H9: ='Table 2'!B9*'Table 1'!Q13/1000 -> 2.8869096 | I9: ='Table 2'!B9*'Table 1'!Q13/1000*SQRT(('Table 2'!C9/'Table 2'!B9)^2+('Table 1'!R13/'Table 1'!Q13)^2) -> 1.5756809 | J9: ='Table 3'!D9 -> 1.6585187 | K9: ='Table 3'!E9 -> 0.92375292 | L9: ='Table 2'!F9*'Table 1'!Q13/1000 -> 2.1435775 | M9: ='Table 2'!F9*'Table 1'!Q13/1000*SQRT(('Table 2'!G9/'Table 2'!F9)^2+('Table 1'!R13/'Table 1'!Q13)^2) -> 1.2183031 | N9: =AVERAGE(B9,H9) -> 3.4905787 | O9: =SQRT((C9)^2+(I9)^2)/2 -> 0.92943145 | P9: =AVERAGE(D9,J9) -> 2.0053244 | Q9: =SQRT((E9)^2+(K9)^2)/2 -> 0.55733488 | R9: =AVERAGE(F9,L9) -> 2.5918117 | S9: =SQRT((G9)^2+(M9)^2)/2 -> 0.75044405 | T9: =H9/B9 -> 0.70511354
A10: 120 | B10: ='Table 2'!B10*'Table 1'!O14/1000 -> 3.4815005 | C10: ='Table 2'!B10*'Table 1'!O14/1000*SQRT(('Table 2'!C10/'Table 2'!B10)^2+('Table 1'!P14/'Table 1'!O14)^2) -> 1.0007132 | D10: ='Table 3'!B10 -> 2.0195958 | E10: ='Table 3'!C10 -> 0.65644783 | F10: ='Table 2'!F10*'Table 1'!O14/1000 -> 2.8515637 | G10: ='Table 2'!F10*'Table 1'!O14/1000*SQRT(('Table 2'!G10/'Table 2'!F10)^2+('Table 1'!P14/'Table 1'!O14)^2) -> 0.96337841 | H10: ='Table 2'!B10*'Table 1'!Q14/1000 -> 2.5010459 | I10: ='Table 2'!B10*'Table 1'!Q14/1000*SQRT(('Table 2'!C10/'Table 2'!B10)^2+('Table 1'!R14/'Table 1'!Q14)^2) -> 1.6720974 | J10: ='Table 3'!D10 -> 1.4508405 | K10: ='Table 3'!E10 -> 0.99464795 | L10: ='Table 2'!F10*'Table 1'!Q14/1000 -> 2.0485109 | M10: ='Table 2'!F10*'Table 1'!Q14/1000*SQRT(('Table 2'!G10/'Table 2'!F10)^2+('Table 1'!R14/'Table 1'!Q14)^2) -> 1.4170137 | N10: =AVERAGE(B10,H10) -> 2.9912732 | O10: =SQRT((C10)^2+(I10)^2)/2 -> 0.97433779 | P10: =AVERAGE(D10,J10) -> 1.7352182 | Q10: =SQRT((E10)^2+(K10)^2)/2 -> 0.59587085 | R10: =AVERAGE(F10,L10) -> 2.4500373 | S10: =SQRT((G10)^2+(M10)^2)/2 -> 0.85674176 | T10: =H10/B10 -> 0.7183816
A11: 150 | B11: ='Table 2'!B11*'Table 1'!O15/1000 -> 2.5649764 | C11: ='Table 2'!B11*'Table 1'!O15/1000*SQRT(('Table 2'!C11/'Table 2'!B11)^2+('Table 1'!P15/'Table 1'!O15)^2) -> 0.87160213 | D11: ='Table 3'!B11 -> 1.5461232 | E11: ='Table 3'!C11 -> 0.61730172 | F11: ='Table 2'!F11*'Table 1'!O15/1000 -> 2.5585978 | G11: ='Table 2'!F11*'Table 1'!O15/1000*SQRT(('Table 2'!G11/'Table 2'!F11)^2+('Table 1'!P15/'Table 1'!O15)^2) -> 1.0167073 | H11: ='Table 2'!B11*'Table 1'!Q15/1000 -> 1.7433591 | I11: ='Table 2'!B11*'Table 1'!Q15/1000*SQRT(('Table 2'!C11/'Table 2'!B11)^2+('Table 1'!R15/'Table 1'!Q15)^2) -> 1.6158311 | J11: ='Table 3'!D11 -> 1.0508666 | K11: ='Table 3'!E11 -> 0.9985921 | L11: ='Table 2'!F11*'Table 1'!Q15/1000 -> 1.7390237 | M11: ='Table 2'!F11*'Table 1'!Q15/1000*SQRT(('Table 2'!G11/'Table 2'!F11)^2+('Table 1'!R15/'Table 1'!Q15)^2) -> 1.65114 | N11: =AVERAGE(B11,H11) -> 2.1541678 | O11: =SQRT((C11)^2+(I11)^2)/2 -> 0.91795976 | P11: =AVERAGE(D11,J11) -> 1.2984949 | Q11: =SQRT((E11)^2+(K11)^2)/2 -> 0.58699395 | R11: =AVERAGE(F11,L11) -> 2.1488107 | S11: =SQRT((G11)^2+(M11)^2)/2 -> 0.96953044 | T11: =H11/B11 -> 0.67967843
A12: 200 | B12: ='Table 2'!B12*'Table 1'!O16/1000 -> 1.6642773 | C12: ='Table 2'!B12*'Table 1'!O16/1000*SQRT(('Table 2'!C12/'Table 2'!B12)^2+('Table 1'!P16/'Table 1'!O16)^2) -> 0.8039657 | D12: ='Table 3'!B12 -> 1.3181829 | E12: ='Table 3'!C12 -> 0.60544114 | F12: ='Table 2'!F12*'Table 1'!O16/1000 -> 2.7548378 | G12: ='Table 2'!F12*'Table 1'!O16/1000*SQRT(('Table 2'!G12/'Table 2'!F12)^2+('Table 1'!P16/'Table 1'!O16)^2) -> 1.3479801 | H12: ='Table 2'!B12*'Table 1'!Q16/1000 -> 1.0038358 | I12: ='Table 2'!B12*'Table 1'!Q16/1000*SQRT(('Table 2'!C12/'Table 2'!B12)^2+('Table 1'!R16/'Table 1'!Q16)^2) -> 1.6456728 | J12: ='Table 3'!D12 -> 0.79508338 | K12: ='Table 3'!E12 -> 1.2980035 | L12: ='Table 2'!F12*'Table 1'!Q16/1000 -> 1.661625 | M12: ='Table 2'!F12*'Table 1'!Q16/1000*SQRT(('Table 2'!G12/'Table 2'!F12)^2+('Table 1'!R16/'Table 1'!Q16)^2) -> 2.7271163 | N12: =AVERAGE(B12,H12) -> 1.3340566 | O12: =SQRT((C12)^2+(I12)^2)/2 -> 0.91577833 | P12: =AVERAGE(D12,J12) -> 1.0566331 | Q12: =SQRT((E12)^2+(K12)^2)/2 -> 0.71613059 | R12: =AVERAGE(F12,L12) -> 2.2082314 | S12: =SQRT((G12)^2+(M12)^2)/2 -> 1.521037 | T12: =H12/B12 -> 0.6031662
A13: 280 | B13: ='Table 2'!B13*'Table 1'!O17/1000 -> 1.2285954 | C13: ='Table 2'!B13*'Table 1'!O17/1000*SQRT(('Table 2'!C13/'Table 2'!B13)^2+('Table 1'!P17/'Table 1'!O17)^2) -> 0.48908126 | D13: ='Table 3'!B13 -> 1.1504153 | E13: ='Table 3'!C13 -> 0.45340936 | F13: ='Table 2'!F13*'Table 1'!O17/1000 -> 2.759662 | G13: ='Table 2'!F13*'Table 1'!O17/1000*SQRT(('Table 2'!G13/'Table 2'!F13)^2+('Table 1'!P17/'Table 1'!O17)^2) -> 1.2915128 | H13: ='Table 2'!B13*'Table 1'!Q17/1000 -> 1.133634 | I13: ='Table 2'!B13*'Table 1'!Q17/1000*SQRT(('Table 2'!C13/'Table 2'!B13)^2+('Table 1'!R17/'Table 1'!Q17)^2) -> 1.4327133 | J13: ='Table 3'!D13 -> 1.0614967 | K13: ='Table 3'!E13 -> 1.340228 | L13: ='Table 2'!F13*'Table 1'!Q17/1000 -> 2.5463604 | M13: ='Table 2'!F13*'Table 1'!Q17/1000*SQRT(('Table 2'!G13/'Table 2'!F13)^2+('Table 1'!R17/'Table 1'!Q17)^2) -> 3.278583 | N13: =AVERAGE(B13,H13) -> 1.1811147 | O13: =SQRT((C13)^2+(I13)^2)/2 -> 0.75694584 | P13: =AVERAGE(D13,J13) -> 1.105956 | Q13: =SQRT((E13)^2+(K13)^2)/2 -> 0.70742336 | R13: =AVERAGE(F13,L13) -> 2.6530112 | S13: =SQRT((G13)^2+(M13)^2)/2 -> 1.7618961 | T13: =H13/B13 -> 0.92270737
A14: 330 | B14: ='Table 2'!B14*'Table 1'!O18/1000 -> 1.2983039 | C14: ='Table 2'!B14*'Table 1'!O18/1000*SQRT(('Table 2'!C14/'Table 2'!B14)^2+('Table 1'!P18/'Table 1'!O18)^2) -> 0.79980503 | D14: ='Table 3'!B14 -> 1.3753882 | E14: ='Table 3'!C14 -> 0.86075736 | F14: ='Table 2'!F14*'Table 1'!O18/1000 -> 3.5663939 | G14: ='Table 2'!F14*'Table 1'!O18/1000*SQRT(('Table 2'!G14/'Table 2'!F14)^2+('Table 1'!P18/'Table 1'!O18)^2) -> 2.4803899 | H14: ='Table 2'!B14*'Table 1'!Q18/1000 -> 1.1265236 | I14: ='Table 2'!B14*'Table 1'!Q18/1000*SQRT(('Table 2'!C14/'Table 2'!B14)^2+('Table 1'!R18/'Table 1'!Q18)^2) -> 1.7445076 | J14: ='Table 3'!D14 -> 1.1934087 | K14: ='Table 3'!E14 -> 1.8527632 | L14: ='Table 2'!F14*'Table 1'!Q18/1000 -> 3.0945195 | M14: ='Table 2'!F14*'Table 1'!Q18/1000*SQRT(('Table 2'!G14/'Table 2'!F14)^2+('Table 1'!R18/'Table 1'!Q18)^2) -> 4.895106 | N14: =AVERAGE(B14,H14) -> 1.2124137 | O14: =SQRT((C14)^2+(I14)^2)/2 -> 0.9595565 | P14: =AVERAGE(D14,J14) -> 1.2843984 | Q14: =SQRT((E14)^2+(K14)^2)/2 -> 1.0214738 | R14: =AVERAGE(F14,L14) -> 3.3304567 | S14: =SQRT((G14)^2+(M14)^2)/2 -> 2.7438293 | T14: =H14/B14 -> 0.86768863
A15: 500 | B15: ='Table 2'!B15*'Table 1'!O19/1000 -> 1.2547691 | C15: ='Table 2'!B15*'Table 1'!O19/1000*SQRT(('Table 2'!C15/'Table 2'!B15)^2+('Table 1'!P19/'Table 1'!O19)^2) -> 0.93109966 | D15: ='Table 3'!B15 -> 1.3389599 | E15: ='Table 3'!C15 -> 1.0101789 | F15: ='Table 2'!F15*'Table 1'!O19/1000 -> 2.7905971 | G15: ='Table 2'!F15*'Table 1'!O19/1000*SQRT(('Table 2'!G15/'Table 2'!F15)^2+('Table 1'!P19/'Table 1'!O19)^2) -> 2.1852928 | H15: ='Table 2'!B15*'Table 1'!Q19/1000 -> 0.91721135 | I15: ='Table 2'!B15*'Table 1'!Q19/1000*SQRT(('Table 2'!C15/'Table 2'!B15)^2+('Table 1'!R19/'Table 1'!Q19)^2) -> 2.0055696 | J15: ='Table 3'!D15 -> 0.97875317 | K15: ='Table 3'!E15 -> 2.1442863 | L15: ='Table 2'!F15*'Table 1'!Q19/1000 -> 2.0398712 | M15: ='Table 2'!F15*'Table 1'!Q19/1000*SQRT(('Table 2'!G15/'Table 2'!F15)^2+('Table 1'!R19/'Table 1'!Q19)^2) -> 4.4894748 | N15: =AVERAGE(B15,H15) -> 1.0859902 | O15: =SQRT((C15)^2+(I15)^2)/2 -> 1.1055831 | P15: =AVERAGE(D15,J15) -> 1.1588566 | Q15: =SQRT((E15)^2+(K15)^2)/2 -> 1.1851609 | R15: =AVERAGE(F15,L15) -> 2.4152342 | S15: =SQRT((G15)^2+(M15)^2)/2 -> 2.496542 | T15: =H15/B15 -> 0.73098017
A16: Notes:
A17: aPOC fluxes were calculated by multiplying each C/Th ratio (Table 2) by the cruise average steady-state 234Th flux (Table 1) at a given depth
A18: bPOC fluxes were calculated by multiplying each C/Th ratio (Table 2) by the non-steady-state 234Th flux (Table 1) at a given depth
A19: a,bPOC flux uncertainties were calculated by propagating the C/Th ratio and 234Th flux uncertainties
A20: cAverage POC flux was calculated averaging the SS and NSS POC flux estimates using each C/Th ratio. Uncertainties were calculated by propagating the uncertainties of the SS and NSS POC flux estimates
